[2024-12-14T11:10:27.211+0000] {local_task_job_runner.py:120} INFO - ::group::Pre task execution logs
[2024-12-14T11:10:27.430+0000] {taskinstance.py:2076} INFO - Dependencies all met for dep_context=non-requeueable deps ti=<TaskInstance: migration_fit_schema.insert_data.insert_data_employee manual__2024-12-14T11:10:21.354935+00:00 [queued]>
[2024-12-14T11:10:27.442+0000] {taskinstance.py:2076} INFO - Dependencies all met for dep_context=requeueable deps ti=<TaskInstance: migration_fit_schema.insert_data.insert_data_employee manual__2024-12-14T11:10:21.354935+00:00 [queued]>
[2024-12-14T11:10:27.442+0000] {taskinstance.py:2306} INFO - Starting attempt 1 of 1
[2024-12-14T11:10:27.460+0000] {taskinstance.py:2330} INFO - Executing <Task(PythonOperator): insert_data.insert_data_employee> on 2024-12-14 11:10:21.354935+00:00
[2024-12-14T11:10:27.468+0000] {warnings.py:110} WARNING - /home/***/.local/lib/python3.12/site-packages/***/task/task_runner/standard_task_runner.py:61: DeprecationWarning: This process (pid=88) is multi-threaded, use of fork() may lead to deadlocks in the child.
  pid = os.fork()

[2024-12-14T11:10:27.470+0000] {standard_task_runner.py:63} INFO - Started process 90 to run task
[2024-12-14T11:10:27.472+0000] {standard_task_runner.py:90} INFO - Running: ['***', 'tasks', 'run', 'migration_fit_schema', 'insert_data.insert_data_employee', 'manual__2024-12-14T11:10:21.354935+00:00', '--job-id', '4', '--raw', '--subdir', 'DAGS_FOLDER/etl_migrate.py', '--cfg-path', '/tmp/tmpickoo92o']
[2024-12-14T11:10:27.475+0000] {standard_task_runner.py:91} INFO - Job 4: Subtask insert_data.insert_data_employee
[2024-12-14T11:10:27.547+0000] {task_command.py:426} INFO - Running <TaskInstance: migration_fit_schema.insert_data.insert_data_employee manual__2024-12-14T11:10:21.354935+00:00 [running]> on host 472b63b715e1
[2024-12-14T11:10:27.657+0000] {taskinstance.py:2648} INFO - Exporting env vars: AIRFLOW_CTX_DAG_OWNER='***' AIRFLOW_CTX_DAG_ID='migration_fit_schema' AIRFLOW_CTX_TASK_ID='insert_data.insert_data_employee' AIRFLOW_CTX_EXECUTION_DATE='2024-12-14T11:10:21.354935+00:00' AIRFLOW_CTX_TRY_NUMBER='1' AIRFLOW_CTX_DAG_RUN_ID='manual__2024-12-14T11:10:21.354935+00:00'
[2024-12-14T11:10:27.659+0000] {taskinstance.py:430} INFO - ::endgroup::
[2024-12-14T11:10:27.956+0000] {logging_mixin.py:188} INFO - Transaction failed for table employee: name 'np' is not defined
[2024-12-14T11:10:27.957+0000] {taskinstance.py:441} INFO - ::group::Post task execution logs
[2024-12-14T11:10:27.957+0000] {taskinstance.py:2905} ERROR - Task failed with exception
Traceback (most recent call last):
  File "/home/airflow/.local/lib/python3.12/site-packages/airflow/models/taskinstance.py", line 465, in _execute_task
    result = _execute_callable(context=context, **execute_callable_kwargs)
             ^^^^^^^^^^^^^^^^^^^^^^^^^^^^^^^^^^^^^^^^^^^^^^^^^^^^^^^^^^^^^
  File "/home/airflow/.local/lib/python3.12/site-packages/airflow/models/taskinstance.py", line 432, in _execute_callable
    return execute_callable(context=context, **execute_callable_kwargs)
           ^^^^^^^^^^^^^^^^^^^^^^^^^^^^^^^^^^^^^^^^^^^^^^^^^^^^^^^^^^^^
  File "/home/airflow/.local/lib/python3.12/site-packages/airflow/models/baseoperator.py", line 400, in wrapper
    return func(self, *args, **kwargs)
           ^^^^^^^^^^^^^^^^^^^^^^^^^^^
  File "/home/airflow/.local/lib/python3.12/site-packages/airflow/operators/python.py", line 235, in execute
    return_value = self.execute_callable()
                   ^^^^^^^^^^^^^^^^^^^^^^^
  File "/home/airflow/.local/lib/python3.12/site-packages/airflow/operators/python.py", line 252, in execute_callable
    return self.python_callable(*self.op_args, **self.op_kwargs)
           ^^^^^^^^^^^^^^^^^^^^^^^^^^^^^^^^^^^^^^^^^^^^^^^^^^^^^
  File "/opt/airflow/dags/tasks/etl_task.py", line 111, in insert_data
    raise e
  File "/opt/airflow/dags/tasks/etl_task.py", line 100, in insert_data
    data = [tuple(sanitize_value(v) for v in row) for row in data]
            ^^^^^^^^^^^^^^^^^^^^^^^^^^^^^^^^^^^^^
  File "/opt/airflow/dags/tasks/etl_task.py", line 100, in <genexpr>
    data = [tuple(sanitize_value(v) for v in row) for row in data]
                  ^^^^^^^^^^^^^^^^^
  File "/opt/airflow/dags/tasks/etl_task.py", line 13, in sanitize_value
    if isinstance(value, np.integer):  # Nếu là số nguyên (integer)
                         ^^
NameError: name 'np' is not defined
[2024-12-14T11:10:27.976+0000] {taskinstance.py:1206} INFO - Marking task as FAILED. dag_id=migration_fit_schema, task_id=insert_data.insert_data_employee, run_id=manual__2024-12-14T11:10:21.354935+00:00, execution_date=20241214T111021, start_date=20241214T111027, end_date=20241214T111027
[2024-12-14T11:10:27.992+0000] {standard_task_runner.py:110} ERROR - Failed to execute job 4 for task insert_data.insert_data_employee (name 'np' is not defined; 90)
[2024-12-14T11:10:28.008+0000] {local_task_job_runner.py:240} INFO - Task exited with return code 1
[2024-12-14T11:10:28.037+0000] {taskinstance.py:3498} INFO - 0 downstream tasks scheduled from follow-on schedule check
[2024-12-14T11:10:28.040+0000] {local_task_job_runner.py:222} INFO - ::endgroup::
