[2024-12-13T20:27:45.142+0000] {local_task_job_runner.py:120} INFO - ::group::Pre task execution logs
[2024-12-13T20:27:45.329+0000] {taskinstance.py:2076} INFO - Dependencies all met for dep_context=non-requeueable deps ti=<TaskInstance: etl_data.insert_data.rename_directories manual__2024-12-13T20:27:15.522338+00:00 [queued]>
[2024-12-13T20:27:45.337+0000] {taskinstance.py:2076} INFO - Dependencies all met for dep_context=requeueable deps ti=<TaskInstance: etl_data.insert_data.rename_directories manual__2024-12-13T20:27:15.522338+00:00 [queued]>
[2024-12-13T20:27:45.337+0000] {taskinstance.py:2306} INFO - Starting attempt 1 of 1
[2024-12-13T20:27:45.348+0000] {taskinstance.py:2330} INFO - Executing <Task(PythonOperator): insert_data.rename_directories> on 2024-12-13 20:27:15.522338+00:00
[2024-12-13T20:27:45.361+0000] {warnings.py:110} WARNING - /home/***/.local/lib/python3.12/site-packages/***/task/task_runner/standard_task_runner.py:61: DeprecationWarning: This process (pid=5441) is multi-threaded, use of fork() may lead to deadlocks in the child.
  pid = os.fork()

[2024-12-13T20:27:45.362+0000] {standard_task_runner.py:63} INFO - Started process 5443 to run task
[2024-12-13T20:27:45.361+0000] {standard_task_runner.py:90} INFO - Running: ['***', 'tasks', 'run', 'etl_data', 'insert_data.rename_directories', 'manual__2024-12-13T20:27:15.522338+00:00', '--job-id', '551', '--raw', '--subdir', 'DAGS_FOLDER/etl_data.py', '--cfg-path', '/tmp/tmpx8_1ohgs']
[2024-12-13T20:27:45.363+0000] {standard_task_runner.py:91} INFO - Job 551: Subtask insert_data.rename_directories
[2024-12-13T20:27:45.412+0000] {task_command.py:426} INFO - Running <TaskInstance: etl_data.insert_data.rename_directories manual__2024-12-13T20:27:15.522338+00:00 [running]> on host 1fe973f28a1c
[2024-12-13T20:27:45.498+0000] {taskinstance.py:2648} INFO - Exporting env vars: AIRFLOW_CTX_DAG_OWNER='***' AIRFLOW_CTX_DAG_ID='etl_data' AIRFLOW_CTX_TASK_ID='insert_data.rename_directories' AIRFLOW_CTX_EXECUTION_DATE='2024-12-13T20:27:15.522338+00:00' AIRFLOW_CTX_TRY_NUMBER='1' AIRFLOW_CTX_DAG_RUN_ID='manual__2024-12-13T20:27:15.522338+00:00'
[2024-12-13T20:27:45.499+0000] {taskinstance.py:430} INFO - ::endgroup::
[2024-12-13T20:27:45.500+0000] {taskinstance.py:441} INFO - ::group::Post task execution logs
[2024-12-13T20:27:45.501+0000] {taskinstance.py:2905} ERROR - Task failed with exception
Traceback (most recent call last):
  File "/home/airflow/.local/lib/python3.12/site-packages/airflow/models/taskinstance.py", line 465, in _execute_task
    result = _execute_callable(context=context, **execute_callable_kwargs)
             ^^^^^^^^^^^^^^^^^^^^^^^^^^^^^^^^^^^^^^^^^^^^^^^^^^^^^^^^^^^^^
  File "/home/airflow/.local/lib/python3.12/site-packages/airflow/models/taskinstance.py", line 432, in _execute_callable
    return execute_callable(context=context, **execute_callable_kwargs)
           ^^^^^^^^^^^^^^^^^^^^^^^^^^^^^^^^^^^^^^^^^^^^^^^^^^^^^^^^^^^^
  File "/home/airflow/.local/lib/python3.12/site-packages/airflow/models/baseoperator.py", line 400, in wrapper
    return func(self, *args, **kwargs)
           ^^^^^^^^^^^^^^^^^^^^^^^^^^^
  File "/home/airflow/.local/lib/python3.12/site-packages/airflow/operators/python.py", line 235, in execute
    return_value = self.execute_callable()
                   ^^^^^^^^^^^^^^^^^^^^^^^
  File "/home/airflow/.local/lib/python3.12/site-packages/airflow/operators/python.py", line 252, in execute_callable
    return self.python_callable(*self.op_args, **self.op_kwargs)
           ^^^^^^^^^^^^^^^^^^^^^^^^^^^^^^^^^^^^^^^^^^^^^^^^^^^^^
  File "/opt/airflow/dags/tasks/etl_task.py", line 120, in rename_directories
    os.rename(current_dir, new_dir)
PermissionError: [Errno 13] Permission denied: '/opt/airflow/dags/data/K16_current' -> '/opt/airflow/dags/data/K16'
[2024-12-13T20:27:45.509+0000] {taskinstance.py:1206} INFO - Marking task as FAILED. dag_id=etl_data, task_id=insert_data.rename_directories, run_id=manual__2024-12-13T20:27:15.522338+00:00, execution_date=20241213T202715, start_date=20241213T202745, end_date=20241213T202745
[2024-12-13T20:27:45.518+0000] {standard_task_runner.py:110} ERROR - Failed to execute job 551 for task insert_data.rename_directories ([Errno 13] Permission denied: '/opt/airflow/dags/data/K16_current' -> '/opt/airflow/dags/data/K16'; 5443)
[2024-12-13T20:27:45.537+0000] {local_task_job_runner.py:240} INFO - Task exited with return code 1
[2024-12-13T20:27:45.569+0000] {taskinstance.py:3498} INFO - 0 downstream tasks scheduled from follow-on schedule check
[2024-12-13T20:27:45.571+0000] {local_task_job_runner.py:222} INFO - ::endgroup::
