[2024-12-14T07:54:20.672+0000] {local_task_job_runner.py:120} INFO - ::group::Pre task execution logs
[2024-12-14T07:54:20.692+0000] {taskinstance.py:2076} INFO - Dependencies all met for dep_context=non-requeueable deps ti=<TaskInstance: etl_data.insert_data.insert_data_instruction_fact manual__2024-12-14T07:54:08.554760+00:00 [queued]>
[2024-12-14T07:54:20.699+0000] {taskinstance.py:2076} INFO - Dependencies all met for dep_context=requeueable deps ti=<TaskInstance: etl_data.insert_data.insert_data_instruction_fact manual__2024-12-14T07:54:08.554760+00:00 [queued]>
[2024-12-14T07:54:20.700+0000] {taskinstance.py:2306} INFO - Starting attempt 1 of 1
[2024-12-14T07:54:20.710+0000] {taskinstance.py:2330} INFO - Executing <Task(PythonOperator): insert_data.insert_data_instruction_fact> on 2024-12-14 07:54:08.554760+00:00
[2024-12-14T07:54:20.723+0000] {warnings.py:110} WARNING - /home/***/.local/lib/python3.12/site-packages/***/task/task_runner/standard_task_runner.py:61: DeprecationWarning: This process (pid=15330) is multi-threaded, use of fork() may lead to deadlocks in the child.
  pid = os.fork()

[2024-12-14T07:54:20.725+0000] {standard_task_runner.py:63} INFO - Started process 15332 to run task
[2024-12-14T07:54:20.730+0000] {standard_task_runner.py:90} INFO - Running: ['***', 'tasks', 'run', 'etl_data', 'insert_data.insert_data_instruction_fact', 'manual__2024-12-14T07:54:08.554760+00:00', '--job-id', '1027', '--raw', '--subdir', 'DAGS_FOLDER/etl_data.py', '--cfg-path', '/tmp/tmpneatqg08']
[2024-12-14T07:54:20.735+0000] {standard_task_runner.py:91} INFO - Job 1027: Subtask insert_data.insert_data_instruction_fact
[2024-12-14T07:54:20.794+0000] {task_command.py:426} INFO - Running <TaskInstance: etl_data.insert_data.insert_data_instruction_fact manual__2024-12-14T07:54:08.554760+00:00 [running]> on host 1fe973f28a1c
[2024-12-14T07:54:20.887+0000] {taskinstance.py:2648} INFO - Exporting env vars: AIRFLOW_CTX_DAG_OWNER='***' AIRFLOW_CTX_DAG_ID='etl_data' AIRFLOW_CTX_TASK_ID='insert_data.insert_data_instruction_fact' AIRFLOW_CTX_EXECUTION_DATE='2024-12-14T07:54:08.554760+00:00' AIRFLOW_CTX_TRY_NUMBER='1' AIRFLOW_CTX_DAG_RUN_ID='manual__2024-12-14T07:54:08.554760+00:00'
[2024-12-14T07:54:20.889+0000] {taskinstance.py:430} INFO - ::endgroup::
[2024-12-14T07:54:21.324+0000] {logging_mixin.py:188} INFO - Transaction failed for table instruction_fact: bigint out of range
[2024-12-14T07:54:21.352+0000] {taskinstance.py:441} INFO - ::group::Post task execution logs
[2024-12-14T07:54:21.353+0000] {taskinstance.py:2905} ERROR - Task failed with exception
Traceback (most recent call last):
  File "/home/airflow/.local/lib/python3.12/site-packages/airflow/models/taskinstance.py", line 465, in _execute_task
    result = _execute_callable(context=context, **execute_callable_kwargs)
             ^^^^^^^^^^^^^^^^^^^^^^^^^^^^^^^^^^^^^^^^^^^^^^^^^^^^^^^^^^^^^
  File "/home/airflow/.local/lib/python3.12/site-packages/airflow/models/taskinstance.py", line 432, in _execute_callable
    return execute_callable(context=context, **execute_callable_kwargs)
           ^^^^^^^^^^^^^^^^^^^^^^^^^^^^^^^^^^^^^^^^^^^^^^^^^^^^^^^^^^^^
  File "/home/airflow/.local/lib/python3.12/site-packages/airflow/models/baseoperator.py", line 400, in wrapper
    return func(self, *args, **kwargs)
           ^^^^^^^^^^^^^^^^^^^^^^^^^^^
  File "/home/airflow/.local/lib/python3.12/site-packages/airflow/operators/python.py", line 235, in execute
    return_value = self.execute_callable()
                   ^^^^^^^^^^^^^^^^^^^^^^^
  File "/home/airflow/.local/lib/python3.12/site-packages/airflow/operators/python.py", line 252, in execute_callable
    return self.python_callable(*self.op_args, **self.op_kwargs)
           ^^^^^^^^^^^^^^^^^^^^^^^^^^^^^^^^^^^^^^^^^^^^^^^^^^^^^
  File "/opt/airflow/dags/tasks/etl_task.py", line 98, in insert_data
    raise e
  File "/opt/airflow/dags/tasks/etl_task.py", line 90, in insert_data
    execute_values(cursor, insert_query, data, template=f"({placeholders})", page_size=1000)
  File "/home/airflow/.local/lib/python3.12/site-packages/psycopg2/extras.py", line 1299, in execute_values
    cur.execute(b''.join(parts))
psycopg2.errors.NumericValueOutOfRange: bigint out of range

[2024-12-14T07:54:21.382+0000] {taskinstance.py:1206} INFO - Marking task as FAILED. dag_id=etl_data, task_id=insert_data.insert_data_instruction_fact, run_id=manual__2024-12-14T07:54:08.554760+00:00, execution_date=20241214T075408, start_date=20241214T075420, end_date=20241214T075421
[2024-12-14T07:54:21.412+0000] {standard_task_runner.py:110} ERROR - Failed to execute job 1027 for task insert_data.insert_data_instruction_fact (bigint out of range
; 15332)
[2024-12-14T07:54:21.467+0000] {local_task_job_runner.py:240} INFO - Task exited with return code 1
[2024-12-14T07:54:21.494+0000] {taskinstance.py:3498} INFO - 0 downstream tasks scheduled from follow-on schedule check
[2024-12-14T07:54:21.497+0000] {local_task_job_runner.py:222} INFO - ::endgroup::
