[2024-12-15T08:10:41.301+0000] {local_task_job_runner.py:120} INFO - ::group::Pre task execution logs
[2024-12-15T08:10:41.493+0000] {taskinstance.py:2076} INFO - Dependencies all met for dep_context=non-requeueable deps ti=<TaskInstance: etl_data.insert_data.insert_data_course manual__2024-12-15T08:10:39.920864+00:00 [queued]>
[2024-12-15T08:10:41.500+0000] {taskinstance.py:2076} INFO - Dependencies all met for dep_context=requeueable deps ti=<TaskInstance: etl_data.insert_data.insert_data_course manual__2024-12-15T08:10:39.920864+00:00 [queued]>
[2024-12-15T08:10:41.500+0000] {taskinstance.py:2306} INFO - Starting attempt 1 of 1
[2024-12-15T08:10:41.512+0000] {taskinstance.py:2330} INFO - Executing <Task(PythonOperator): insert_data.insert_data_course> on 2024-12-15 08:10:39.920864+00:00
[2024-12-15T08:10:41.519+0000] {warnings.py:110} WARNING - /home/***/.local/lib/python3.12/site-packages/***/task/task_runner/standard_task_runner.py:61: DeprecationWarning: This process (pid=3272) is multi-threaded, use of fork() may lead to deadlocks in the child.
  pid = os.fork()

[2024-12-15T08:10:41.521+0000] {standard_task_runner.py:63} INFO - Started process 3274 to run task
[2024-12-15T08:10:41.523+0000] {standard_task_runner.py:90} INFO - Running: ['***', 'tasks', 'run', 'etl_data', 'insert_data.insert_data_course', 'manual__2024-12-15T08:10:39.920864+00:00', '--job-id', '491', '--raw', '--subdir', 'DAGS_FOLDER/etl_data.py', '--cfg-path', '/tmp/tmp0c5hx0b_']
[2024-12-15T08:10:41.526+0000] {standard_task_runner.py:91} INFO - Job 491: Subtask insert_data.insert_data_course
[2024-12-15T08:10:41.583+0000] {task_command.py:426} INFO - Running <TaskInstance: etl_data.insert_data.insert_data_course manual__2024-12-15T08:10:39.920864+00:00 [running]> on host 2f4e9c743994
[2024-12-15T08:10:41.749+0000] {taskinstance.py:2648} INFO - Exporting env vars: AIRFLOW_CTX_DAG_OWNER='***' AIRFLOW_CTX_DAG_ID='etl_data' AIRFLOW_CTX_TASK_ID='insert_data.insert_data_course' AIRFLOW_CTX_EXECUTION_DATE='2024-12-15T08:10:39.920864+00:00' AIRFLOW_CTX_TRY_NUMBER='1' AIRFLOW_CTX_DAG_RUN_ID='manual__2024-12-15T08:10:39.920864+00:00'
[2024-12-15T08:10:41.751+0000] {taskinstance.py:430} INFO - ::endgroup::
[2024-12-15T08:10:42.253+0000] {logging_mixin.py:188} INFO - Transaction failed for table course: Path must be absolute, was given dataraw/course/
[2024-12-15T08:10:42.254+0000] {taskinstance.py:441} INFO - ::group::Post task execution logs
[2024-12-15T08:10:42.254+0000] {taskinstance.py:2905} ERROR - Task failed with exception
Traceback (most recent call last):
  File "/home/airflow/.local/lib/python3.12/site-packages/airflow/models/taskinstance.py", line 465, in _execute_task
    result = _execute_callable(context=context, **execute_callable_kwargs)
             ^^^^^^^^^^^^^^^^^^^^^^^^^^^^^^^^^^^^^^^^^^^^^^^^^^^^^^^^^^^^^
  File "/home/airflow/.local/lib/python3.12/site-packages/airflow/models/taskinstance.py", line 432, in _execute_callable
    return execute_callable(context=context, **execute_callable_kwargs)
           ^^^^^^^^^^^^^^^^^^^^^^^^^^^^^^^^^^^^^^^^^^^^^^^^^^^^^^^^^^^^
  File "/home/airflow/.local/lib/python3.12/site-packages/airflow/models/baseoperator.py", line 400, in wrapper
    return func(self, *args, **kwargs)
           ^^^^^^^^^^^^^^^^^^^^^^^^^^^
  File "/home/airflow/.local/lib/python3.12/site-packages/airflow/operators/python.py", line 235, in execute
    return_value = self.execute_callable()
                   ^^^^^^^^^^^^^^^^^^^^^^^
  File "/home/airflow/.local/lib/python3.12/site-packages/airflow/operators/python.py", line 252, in execute_callable
    return self.python_callable(*self.op_args, **self.op_kwargs)
           ^^^^^^^^^^^^^^^^^^^^^^^^^^^^^^^^^^^^^^^^^^^^^^^^^^^^^
  File "/opt/airflow/dags/tasks/etl_task.py", line 125, in insert_data
    raise e
  File "/opt/airflow/dags/tasks/etl_task.py", line 113, in insert_data
    if not hdfs_client.exists(hdfs_path):
           ^^^^^^^^^^^^^^^^^^^^^^^^^^^^^
  File "/home/airflow/.local/lib/python3.12/site-packages/pyhdfs/__init__.py", line 832, in exists
    self.get_file_status(path, **kwargs)
  File "/home/airflow/.local/lib/python3.12/site-packages/pyhdfs/__init__.py", line 615, in get_file_status
    return FileStatus(**_json(self._get(path, 'GETFILESTATUS', **kwargs))['FileStatus'])
                              ^^^^^^^^^^^^^^^^^^^^^^^^^^^^^^^^^^^^^^^^^^
  File "/home/airflow/.local/lib/python3.12/site-packages/pyhdfs/__init__.py", line 450, in _get
    return self._request('get', path, op, expected_status, **kwargs)
           ^^^^^^^^^^^^^^^^^^^^^^^^^^^^^^^^^^^^^^^^^^^^^^^^^^^^^^^^^
  File "/home/airflow/.local/lib/python3.12/site-packages/pyhdfs/__init__.py", line 407, in _request
    hosts, path = self._parse_path(path)
                  ^^^^^^^^^^^^^^^^^^^^^^
  File "/home/airflow/.local/lib/python3.12/site-packages/pyhdfs/__init__.py", line 372, in _parse_path
    raise ValueError("Path must be absolute, was given {}".format(path))
ValueError: Path must be absolute, was given dataraw/course/
[2024-12-15T08:10:42.269+0000] {taskinstance.py:1206} INFO - Marking task as FAILED. dag_id=etl_data, task_id=insert_data.insert_data_course, run_id=manual__2024-12-15T08:10:39.920864+00:00, execution_date=20241215T081039, start_date=20241215T081041, end_date=20241215T081042
[2024-12-15T08:10:42.281+0000] {standard_task_runner.py:110} ERROR - Failed to execute job 491 for task insert_data.insert_data_course (Path must be absolute, was given dataraw/course/; 3274)
[2024-12-15T08:10:42.302+0000] {local_task_job_runner.py:240} INFO - Task exited with return code 1
[2024-12-15T08:10:42.344+0000] {taskinstance.py:3498} INFO - 0 downstream tasks scheduled from follow-on schedule check
[2024-12-15T08:10:42.347+0000] {local_task_job_runner.py:222} INFO - ::endgroup::
