[2024-12-13T20:29:59.296+0000] {local_task_job_runner.py:120} INFO - ::group::Pre task execution logs
[2024-12-13T20:29:59.484+0000] {taskinstance.py:2076} INFO - Dependencies all met for dep_context=non-requeueable deps ti=<TaskInstance: etl_data.insert_data.rename_directories manual__2024-12-13T20:29:29.769099+00:00 [queued]>
[2024-12-13T20:29:59.493+0000] {taskinstance.py:2076} INFO - Dependencies all met for dep_context=requeueable deps ti=<TaskInstance: etl_data.insert_data.rename_directories manual__2024-12-13T20:29:29.769099+00:00 [queued]>
[2024-12-13T20:29:59.494+0000] {taskinstance.py:2306} INFO - Starting attempt 1 of 1
[2024-12-13T20:29:59.504+0000] {taskinstance.py:2330} INFO - Executing <Task(PythonOperator): insert_data.rename_directories> on 2024-12-13 20:29:29.769099+00:00
[2024-12-13T20:29:59.511+0000] {warnings.py:110} WARNING - /home/***/.local/lib/python3.12/site-packages/***/task/task_runner/standard_task_runner.py:61: DeprecationWarning: This process (pid=5505) is multi-threaded, use of fork() may lead to deadlocks in the child.
  pid = os.fork()

[2024-12-13T20:29:59.513+0000] {standard_task_runner.py:63} INFO - Started process 5507 to run task
[2024-12-13T20:29:59.516+0000] {standard_task_runner.py:90} INFO - Running: ['***', 'tasks', 'run', 'etl_data', 'insert_data.rename_directories', 'manual__2024-12-13T20:29:29.769099+00:00', '--job-id', '563', '--raw', '--subdir', 'DAGS_FOLDER/etl_data.py', '--cfg-path', '/tmp/tmpjzfyfrii']
[2024-12-13T20:29:59.521+0000] {standard_task_runner.py:91} INFO - Job 563: Subtask insert_data.rename_directories
[2024-12-13T20:29:59.575+0000] {task_command.py:426} INFO - Running <TaskInstance: etl_data.insert_data.rename_directories manual__2024-12-13T20:29:29.769099+00:00 [running]> on host 1fe973f28a1c
[2024-12-13T20:29:59.716+0000] {taskinstance.py:2648} INFO - Exporting env vars: AIRFLOW_CTX_DAG_OWNER='***' AIRFLOW_CTX_DAG_ID='etl_data' AIRFLOW_CTX_TASK_ID='insert_data.rename_directories' AIRFLOW_CTX_EXECUTION_DATE='2024-12-13T20:29:29.769099+00:00' AIRFLOW_CTX_TRY_NUMBER='1' AIRFLOW_CTX_DAG_RUN_ID='manual__2024-12-13T20:29:29.769099+00:00'
[2024-12-13T20:29:59.717+0000] {taskinstance.py:430} INFO - ::endgroup::
[2024-12-13T20:29:59.722+0000] {taskinstance.py:441} INFO - ::group::Post task execution logs
[2024-12-13T20:29:59.722+0000] {taskinstance.py:2905} ERROR - Task failed with exception
Traceback (most recent call last):
  File "/home/airflow/.local/lib/python3.12/site-packages/airflow/models/taskinstance.py", line 465, in _execute_task
    result = _execute_callable(context=context, **execute_callable_kwargs)
             ^^^^^^^^^^^^^^^^^^^^^^^^^^^^^^^^^^^^^^^^^^^^^^^^^^^^^^^^^^^^^
  File "/home/airflow/.local/lib/python3.12/site-packages/airflow/models/taskinstance.py", line 432, in _execute_callable
    return execute_callable(context=context, **execute_callable_kwargs)
           ^^^^^^^^^^^^^^^^^^^^^^^^^^^^^^^^^^^^^^^^^^^^^^^^^^^^^^^^^^^^
  File "/home/airflow/.local/lib/python3.12/site-packages/airflow/models/baseoperator.py", line 400, in wrapper
    return func(self, *args, **kwargs)
           ^^^^^^^^^^^^^^^^^^^^^^^^^^^
  File "/home/airflow/.local/lib/python3.12/site-packages/airflow/operators/python.py", line 235, in execute
    return_value = self.execute_callable()
                   ^^^^^^^^^^^^^^^^^^^^^^^
  File "/home/airflow/.local/lib/python3.12/site-packages/airflow/operators/python.py", line 252, in execute_callable
    return self.python_callable(*self.op_args, **self.op_kwargs)
           ^^^^^^^^^^^^^^^^^^^^^^^^^^^^^^^^^^^^^^^^^^^^^^^^^^^^^
  File "/opt/airflow/dags/tasks/etl_task.py", line 120, in rename_directories
    os.rename(current_dir, new_dir)
PermissionError: [Errno 13] Permission denied: '/opt/airflow/dags/data/K16_current' -> '/opt/airflow/dags/data/K16'
[2024-12-13T20:29:59.741+0000] {taskinstance.py:1206} INFO - Marking task as FAILED. dag_id=etl_data, task_id=insert_data.rename_directories, run_id=manual__2024-12-13T20:29:29.769099+00:00, execution_date=20241213T202929, start_date=20241213T202959, end_date=20241213T202959
[2024-12-13T20:29:59.767+0000] {standard_task_runner.py:110} ERROR - Failed to execute job 563 for task insert_data.rename_directories ([Errno 13] Permission denied: '/opt/airflow/dags/data/K16_current' -> '/opt/airflow/dags/data/K16'; 5507)
[2024-12-13T20:29:59.806+0000] {local_task_job_runner.py:240} INFO - Task exited with return code 1
[2024-12-13T20:29:59.837+0000] {taskinstance.py:3498} INFO - 0 downstream tasks scheduled from follow-on schedule check
[2024-12-13T20:29:59.842+0000] {local_task_job_runner.py:222} INFO - ::endgroup::
